Workbook

Sheet 工程維修單 房務部查閱用
A1: 報修單編號 | B1: 報修日期 | C1: YYYYMM | D1: 報修人 | E1: 反應單位 | F1: 維修地點 | G1: (備註/詳細說明) | H1: 類型 | I1: 上傳圖片 | J1: 優先順序 | K1: 物件 | L1: 檢查處理狀態 | M1: 維修人員 | N1: 完工時間 | O1: 處理狀態 | P1: 待修天數 | Q1: 處理說明 | R1: 驗收說明 | S1: 上傳圖片 | T1: 進度 | U1: 報修日期+1天 | V1: 現在日期時間 | W1: 報修日期+4H | X1: 提醒日期欄位 | Y1: 提醒日期欄位+4H | Z1: 工作性質 | AA1: 待修工時 | AB1: 維修時數 | AC1: 維修費用 | AD1: 委外費用 | AE1: 狀態 | AF1: 結案時間 | AG1: 維修工時 | AH1: 客戶費用(其它用途) | AI1: 比對 | AJ1: Time
A2: In202605-086 | B2: 46153.595 | C2: =TEXT(B2,"YYYYMM") -> 202605 | D2: Ann | E2: 房務部 | F2: 813 | G2: 房內有點悶熱，麻煩調整（補單） | H2: 空調 | J2: 有預進客人 | K2: 主機 | M2: 朱欽光 | O2: 待辦驗 | Q2: 已調整 | U2: 46154 | V2: 46153.625 | W2: 46153 | AA2: 0 | AG2: 0 | AI2: =VLOOKUP(A2,'4月明細'!B:B,1,0) -> #N/A
A3: In202605-085 | B3: 46153.5 | C3: =TEXT(B3,"YYYYMM") -> 202605 | D3: Ann | E3: 房務部 | F3: 813 | G3: 冷氣出風口有黏膠帶_x000D_ 請幫忙移除 | H3: 空調 | I3: IMG_1215.jpeg | J3: 有預進客人 | K3: 主機 | M3: 吳友仁 | O3: 待辦驗 | Q3: 已移除 | U3: 46154 | V3: 46153.624 | W3: 46153 | AA3: 0 | AG3: 0 | AI3: =VLOOKUP(A3,'4月明細'!B:B,1,0) -> #N/A
A4: In202605-084 | B4: 46153.469 | C4: =TEXT(B4,"YYYYMM") -> 202605 | D4: Ann | E4: 房務部 | F4: 806 | G4: 門鈴只有單音 | H4: 內裝 | J4: 空房 | K4: 門 | M4: 吳友仁 | O4: 待辦驗 | Q4: 工單取消 | U4: 46154 | V4: 46153.626 | W4: 46153 | AA4: 0 | AG4: 0 | AI4: =VLOOKUP(A4,'4月明細'!B:B,1,0) -> #N/A
A5: In202605-083 | B5: 46153.381 | C5: =TEXT(B5,"YYYYMM") -> 202605 | D5: 車道哨 | E5: 工程部 | F5: B1 後場 | G5: 昨天修好，今天早上門把又壞掉了 | H5: 內裝 | I5: 1000015999.jpg | J5: 一般 | K5: 門 | O5: 待修中 | U5: 46154 | V5: 46153.533 | W5: 46153 | AA5: 0 | AG5: 0 | AI5: =VLOOKUP(A5,'4月明細'!B:B,1,0) -> #N/A
A6: In202605-082 | B6: 46152.79 | C6: =TEXT(B6,"YYYYMM") -> 202605 | D6: Andy | E6: 客人反應 | F6: 730 | G6: 730 的客人說房間溫度偏低 請協助前往查看 | H6: 空調 | J6: 客人在房內 | K6: 主機 | M6: 吳友仁 | O6: 待辦驗 | Q6: 已調整 | U6: 46153 | V6: 46153.533 | W6: 46152 | AA6: 0 | AG6: 0 | AI6: =VLOOKUP(A6,'4月明細'!B:B,1,0) -> #N/A
A7: In202605-081 | B7: 46152.652 | C7: =TEXT(B7,"YYYYMM") -> 202605 | D7: Ann | E7: 房務部 | F7: 607 | G7: 房門要黏貼木皮 | H7: 內裝 | I7: IMG_1199.jpeg | J7: 空房 | K7: 門 | O7: 待修中 | U7: 46153 | V7: 46153.533 | W7: 46152 | X7: 46153 | AA7: 0 | AG7: 0 | AI7: =VLOOKUP(A7,'4月明細'!B:B,1,0) -> #N/A
A8: In202605-080 | B8: 46151.706 | C8: =TEXT(B8,"YYYYMM") -> 202605 | D8: 姿婷 | E8: 房務部 | F8: 911 | G8: 911 馬桶零件鬆動 補單 | H8: 衛厠 | I8: 1000009947.jpg | J8: 空房 | K8: 馬桶 | M8: 李宗銘 | O8: 待辦驗 | Q8: 已修復 | U8: 46152 | V8: 46153.533 | W8: 46151 | AA8: 0 | AG8: 0 | AI8: =VLOOKUP(A8,'4月明細'!B:B,1,0) -> #N/A
A9: In202605-079 | B9: 46151.704 | C9: =TEXT(B9,"YYYYMM") -> 202605 | D9: Kevin | E9: 客人反應 | F9: 707 | G9: 已請ENG調整過 但客人還是覺得房間太冷 | H9: 空調 | J9: 空房 | K9: 主機 | M9: 李宗銘 | O9: 待辦驗 | Q9: 已調整 | U9: 46152 | V9: 46153.533 | W9: 46151 | AA9: 0 | AG9: 0 | AI9: =VLOOKUP(A9,'4月明細'!B:B,1,0) -> #N/A
A10: In202605-078 | B10: 46151.683 | C10: =TEXT(B10,"YYYYMM") -> 202605 | D10: 姿婷 | E10: 房務部 | F10: 1016 | G10: 1016 溫度一直在24度下不去 很熱 | H10: 空調 | I10: 1000009945.jpg | J10: 空房 | K10: 主機 | M10: 李宗銘 | O10: 待辦驗 | Q10: 已調整 | U10: 46152 | V10: 46153.533 | W10: 46151 | AA10: 0 | AG10: 0 | AI10: =VLOOKUP(A10,'4月明細'!B:B,1,0) -> #N/A
A11: In202605-077 | B11: 46151.683 | C11: =TEXT(B11,"YYYYMM") -> 202605 | D11: 姿婷 | E11: 房務部 | F11: 1016 | G11: 1016 淋浴間門把鬆動 | H11: 衛厠 | I11: 1000009946.jpg | J11: 空房 | K11: 淋浴間 | M11: 李宗銘 | O11: 待辦驗 | Q11: 已修復 | U11: 46152 | V11: 46153.533 | W11: 46151 | AA11: 0 | AG11: 0 | AI11: =VLOOKUP(A11,'4月明細'!B:B,1,0) -> #N/A
A12: In202605-076 | B12: 46151.625 | C12: =TEXT(B12,"YYYYMM") -> 202605 | D12: 姿婷 | E12: 房務部 | F12: 921 | G12: 921 浴缸旁大理石需填縫 有點刮手 | H12: 衛厠 | I12: 1000009940.jpg : https://ap12.ragic.com/sims/file.jsp?a=soutlet001&f=9jedqImoeM%401000009940.jpg 1000009938.jpg : https://ap12.ragic.com/sims/file.jsp?a=soutlet001&f=i9A4AVRbkp%401000009938.jpg | J12: 空房 | K12: 淋浴間 | M12: 李宗銘 | O12: 待辦驗 | Q12: 已修復 | U12: 46152 | V12: 46153.533 | W12: 46151 | AA12: 0 | AG12: 0 | AI12: =VLOOKUP(A12,'4月明細'!B:B,1,0) -> #N/A
A13: In202605-075 | B13: 46151.582 | C13: =TEXT(B13,"YYYYMM") -> 202605 | D13: Ann | E13: 房務部 | F13: 513 | G13: 冰箱不冷 | H13: 凍&藏類設備 | J13: 空房 | K13: 冰箱 (冷凍 & 藏) | M13: 吳友仁 | O13: 待辦驗 | Q13: 工單取消 | U13: 46152 | V13: 46153.533 | W13: 46151 | AA13: 0 | AG13: 0 | AI13: =VLOOKUP(A13,'4月明細'!B:B,1,0) -> #N/A
A14: In202605-074 | B14: 46151.518 | C14: =TEXT(B14,"YYYYMM") -> 202605 | D14: 姿婷 | E14: 房務部 | F14: 912 | G14: 912 淋浴間門把鬆動 | H14: 衛厠 | I14: 1000009935.jpg | J14: 空房 | K14: 淋浴間 | M14: 李宗銘 | O14: 待辦驗 | Q14: 已固定 | U14: 46152 | V14: 46153.533 | W14: 46151 | AA14: 0 | AG14: 0 | AI14: =VLOOKUP(A14,'4月明細'!B:B,1,0) -> #N/A
A15: In202605-073 | B15: 46151.517 | C15: =TEXT(B15,"YYYYMM") -> 202605 | D15: Eric | E15: 房務部 | F15: 819 | G15: 浴缸出水龍頭會滴水 | H15: 給&排水 | I15: 2192.jpg | J15: 空房 | K15: 漏水 | M15: 朱欽光 | O15: 待辦驗 | U15: 46152 | V15: 46153.573 | W15: 46151 | AA15: 0 | AG15: 0 | AI15: =VLOOKUP(A15,'4月明細'!B:B,1,0) -> #N/A
A16: In202605-072 | B16: 46151.512 | C16: =TEXT(B16,"YYYYMM") -> 202605 | D16: Eric | E16: 房務部 | F16: 819 | G16: 浴室天花板吸水 | H16: 給&排水 | J16: 空房 | K16: 漏水 | M16: 李宗銘 | O16: 待辦驗 | Q16: 已處理 | U16: 46152 | V16: 46153.533 | W16: 46151 | AA16: 0 | AG16: 0 | AI16: =VLOOKUP(A16,'4月明細'!B:B,1,0) -> #N/A
A17: In202605-071 | B17: 46151.471 | C17: =TEXT(B17,"YYYYMM") -> 202605 | D17: Annya | E17: 房務部 | F17: 706 | G17: 門鈴沒有聲音 | H17: 內裝 | J17: 有預進客人 | K17: 門 | M17: 李宗銘 | O17: 待辦驗 | Q17: 已修復 | U17: 46152 | V17: 46153.533 | W17: 46151 | AA17: 0 | AG17: 0 | AI17: =VLOOKUP(A17,'4月明細'!B:B,1,0) -> #N/A
A18: In202605-070 | B18: 46151.471 | C18: =TEXT(B18,"YYYYMM") -> 202605 | D18: 姿婷 | E18: 房務部 | F18: 1018 | G18: 1018 馬桶按壓零件鬆動 有預進 | H18: 衛厠 | I18: 1000009931.jpg | J18: 有預進客人 | K18: 馬桶 | M18: 李宗銘 | O18: 待辦驗 | Q18: 已修復 | U18: 46152 | V18: 46153.533 | W18: 46151 | AA18: 0 | AG18: 0 | AI18: =VLOOKUP(A18,'4月明細'!B:B,1,0) -> #N/A
A19: In202605-069 | B19: 46151.468 | C19: =TEXT(B19,"YYYYMM") -> 202605 | D19: Ann | E19: 房務部 | F19: 522 | G19: 淋浴間天花板斑駁 | H19: 內裝 | I19: IMG_1174.jpeg : https://ap12.ragic.com/sims/file.jsp?a=soutlet001&f=WMXoPaY43e%40IMG_1174.jpeg IMG_1175.jpeg : https://ap12.ragic.com/sims/file.jsp?a=soutlet001&f=iVxS0Aearf%40IMG_1175.jpeg IMG_1176.jpeg : https://ap12.ragic.com/sims/file.jsp?a=soutlet001&f=BctIMvXZmw%40IMG_1176.jpeg | J19: 有預進客人 | K19: 天花板 | M19: 李宗銘 | O19: 待辦驗 | Q19: 已補漆 | U19: 46152 | V19: 46153.533 | W19: 46151 | AA19: 0 | AG19: 0 | AI19: =VLOOKUP(A19,'4月明細'!B:B,1,0) -> #N/A
A20: In202605-068 | B20: 46151.451 | C20: =TEXT(B20,"YYYYMM") -> 202605 | D20: Ann | E20: 房務部 | F20: 501 | G20: 客廳冷氣面板顯示錯誤 | H20: 空調 | I20: IMG_1173.jpeg | J20: 空房 | K20: 主機 | O20: 待修中 | U20: 46152 | V20: 46153.533 | W20: 46151 | X20: 46153 | AA20: 0 | AG20: 0 | AI20: =VLOOKUP(A20,'4月明細'!B:B,1,0) -> #N/A
A21: In202605-067 | B21: 46151.383 | C21: =TEXT(B21,"YYYYMM") -> 202605 | D21: FO | E21: 客人反應 | F21: 707 | G21: 客人5/9早上反應冷氣太冷 溫度一直上不來 | H21: 空調 | J21: 客人在房內 | K21: 主機 | M21: 李宗銘 | O21: 待辦驗 | Q21: 已調整 | U21: 46152 | V21: 46153.533 | W21: 46151 | AA21: 0 | AG21: 0 | AI21: =VLOOKUP(A21,'4月明細'!B:B,1,0) -> #N/A
A22: In202605-066 | B22: 46150.818 | C22: =TEXT(B22,"YYYYMM") -> 202605 | D22: Annya | E22: 房務部 | F22: 909 | G22: 止水條斷裂 | H22: 衛厠 | I22: IMG_1582.jpeg | J22: 空房 | K22: 淋浴間 | O22: 待修中 | U22: 46151 | V22: 46153.533 | W22: 46150 | X22: 46153 | AA22: 0 | AG22: 0 | AI22: =VLOOKUP(A22,'4月明細'!B:B,1,0) -> #N/A
A23: In202605-065 | B23: 46150.706 | C23: =TEXT(B23,"YYYYMM") -> 202605 | D23: Annya | E23: 房務部 | F23: 531 | G23: 床頭右球燈不亮 | H23: 照明 | I23: IMG_1600.jpeg | J23: 空房 | K23: 燈具 | M23: 李宗銘 | O23: 待辦驗 | Q23: 已修復 | U23: 46151 | V23: 46153.533 | W23: 46150 | AA23: 0 | AG23: 0 | AI23: =VLOOKUP(A23,'4月明細'!B:B,1,0) -> #N/A
A24: In202605-064 | B24: 46150.705 | C24: =TEXT(B24,"YYYYMM") -> 202605 | D24: Annya | E24: 房務部 | F24: 531 | G24: 客房門房擋片補貼皮 | H24: 內裝 | I24: IMG_1599.jpeg | J24: 空房 | K24: 門 | M24: 李宗銘 | O24: 待辦驗 | Q24: 已修復 | U24: 46151 | V24: 46153.533 | W24: 46150 | AA24: 0 | AG24: 0 | AI24: =VLOOKUP(A24,'4月明細'!B:B,1,0) -> #N/A
A25: In202605-063 | B25: 46150.696 | C25: =TEXT(B25,"YYYYMM") -> 202605 | D25: Annya | E25: 房務部 | F25: 531 | G25: 客房門補貼皮 | H25: 內裝 | I25: IMG_1599.jpeg | J25: 空房 | K25: 門 | M25: 李宗銘 | O25: 待辦驗 | Q25: 已處理 | U25: 46151 | V25: 46153.533 | W25: 46150 | AA25: 0 | AG25: 0 | AI25: =VLOOKUP(A25,'4月明細'!B:B,1,0) -> #N/A
A26: In202605-062 | B26: 46150.617 | C26: =TEXT(B26,"YYYYMM") -> 202605 | D26: Annya | E26: 房務部 | F26: 825 | G26: ‼️同樣問題，第二次呈報工單_x000D_ 天花板二側層板燈：不亮 | H26: 照明 | I26: IMG_1594.jpeg : https://ap12.ragic.com/sims/file.jsp?a=soutlet001&f=hBqc3HKTlQ%40IMG_1594.jpeg IMG_1593.jpeg : https://ap12.ragic.com/sims/file.jsp?a=soutlet001&f=P092p3Nkow%40IMG_1593.jpeg | J26: 空房 | K26: 燈具 | O26: 待修中 | U26: 46151 | V26: 46153.533 | W26: 46150 | X26: 46153 | AA26: 0 | AG26: 0 | AI26: =VLOOKUP(A26,'4月明細'!B:B,1,0) -> #N/A
A27: In202605-061 | B27: 46150.556 | C27: =TEXT(B27,"YYYYMM") -> 202605 | D27: Kevin | E27: 客人反應 | F27: 813 | G27: 空調太熱 | H27: 空調 | J27: 空房 | K27: 分離式冷氣 | O27: 待修中 | U27: 46151 | V27: 46153.533 | W27: 46150 | X27: 46153 | AA27: 0 | AG27: 0 | AI27: =VLOOKUP(A27,'4月明細'!B:B,1,0) -> #N/A
A28: In202605-060 | B28: 46150.543 | C28: =TEXT(B28,"YYYYMM") -> 202605 | D28: Annya | E28: 房務部 | F28: 909 | G28: 止水條斷裂 | H28: 衛厠 | I28: IMG_1582.jpeg | J28: 空房 | K28: 淋浴間 | M28: 黃梓灃 | O28: 待辦驗 | U28: 46151 | V28: 46153.533 | W28: 46150 | AA28: 0 | AG28: 0 | AI28: =VLOOKUP(A28,'4月明細'!B:B,1,0) -> #N/A
A29: In202605-059 | B29: 46150.537 | C29: =TEXT(B29,"YYYYMM") -> 202605 | D29: Annya | E29: 房務部 | F29: 909 | G29: 浴簾卡住 | H29: 衛厠 | I29: IMG_1581.jpeg | J29: 空房 | K29: 浴簾 | M29: 李宗銘 | O29: 待辦驗 | Q29: 已修復 | U29: 46151 | V29: 46153.533 | W29: 46150 | AA29: 0 | AG29: 0 | AI29: =VLOOKUP(A29,'4月明細'!B:B,1,0) -> #N/A
A30: In202605-058 | B30: 46150.516 | C30: =TEXT(B30,"YYYYMM") -> 202605 | D30: Annya | E30: 房務部 | F30: 507 | G30: 電視遙控器無法開啟關閉電視 | H30: 會議設備 | J30: 空房 | K30: 電視 | O30: 待修中 | U30: 46151 | V30: 46153.533 | W30: 46150 | X30: 46153 | AA30: 0 | AG30: 0 | AI30: =VLOOKUP(A30,'4月明細'!B:B,1,0) -> #N/A
A31: In202605-057 | B31: 46150.5 | C31: =TEXT(B31,"YYYYMM") -> 202605 | D31: Annya | E31: 房務部 | F31: 505 | G31: 電視只能on/off，其他選項無法操作 | H31: 會議設備 | J31: 空房 | K31: 電視 | O31: 待修中 | U31: 46151 | V31: 46153.533 | W31: 46150 | X31: 46153 | AA31: 0 | AG31: 0 | AI31: =VLOOKUP(A31,'4月明細'!B:B,1,0) -> #N/A
A32: In202605-056 | B32: 46150.47 | C32: =TEXT(B32,"YYYYMM") -> 202605 | D32: Kevin | E32: 客人反應 | F32: 507 | G32: 電視遙控器 不能使用 | H32: 會議設備 | J32: 空房 | K32: 電視 | O32: 待修中 | U32: 46151 | V32: 46153.533 | W32: 46150 | X32: 46153 | AA32: 0 | AG32: 0 | AI32: =VLOOKUP(A32,'4月明細'!B:B,1,0) -> #N/A
A33: In202605-055 | B33: 46150.44 | C33: =TEXT(B33,"YYYYMM") -> 202605 | D33: Annya | E33: 房務部 | F33: 823 | G33: 客房門卡電池弱電請更換 | H33: 內裝 | I33: IMG_1551.jpeg | J33: 緊急 | K33: 門 | M33: 黃梓灃 | O33: 待辦驗 | U33: 46151 | V33: 46153.533 | W33: 46150 | AA33: 0 | AG33: 0 | AI33: =VLOOKUP(A33,'4月明細'!B:B,1,0) -> #N/A
A34: In202605-054 | B34: 46148.736 | C34: =TEXT(B34,"YYYYMM") -> 202605 | D34: Eric | E34: 房務部 | F34: 515 | G34: 淋浴間矽利康脫落，要重打 | H34: 衛厠 | I34: S__93380627_0.jpg : https://ap12.ragic.com/sims/file.jsp?a=soutlet001&f=XFVTxU3Crl%40S__93380627_0.jpg S__93380628_0.jpg : https://ap12.ragic.com/sims/file.jsp?a=soutlet001&f=MBBbahbRQX%40S__93380628_0.jpg | J34: 空房 | K34: 淋浴間 | M34: 吳友仁 | O34: 待辦驗 | Q34: 已修復 | U34: 46149 | V34: 46153.533 | W34: 46148 | AA34: 0 | AG34: 0 | AI34: =VLOOKUP(A34,'4月明細'!B:B,1,0) -> #N/A
A35: In202605-053 | B35: 46148.708 | C35: =TEXT(B35,"YYYYMM") -> 202605 | D35: Annya | E35: 房務部 | F35: 606 | G35: 淋浴間地板矽利康斷裂發霉 | H35: 衛厠 | I35: IMG_1487.jpeg : https://ap12.ragic.com/sims/file.jsp?a=soutlet001&f=iNlKbSaupb%40IMG_1487.jpeg IMG_1486.jpeg : https://ap12.ragic.com/sims/file.jsp?a=soutlet001&f=hq8MfAYn1M%40IMG_1486.jpeg IMG_1485.jpeg : https://ap12.ragic.com/sims/file.jsp?a=soutlet001&f=2TYPxxFaVd%40IMG_1485.jpeg | J35: 空房 | K35: 淋浴間 | M35: 吳友仁 | O35: 待辦驗 | Q35: 已修復 | U35: 46149 | V35: 46153.533 | W35: 46148 | AA35: 0 | AG35: 0 | AI35: =VLOOKUP(A35,'4月明細'!B:B,1,0) -> #N/A
A36: In202605-052 | B36: 46148.697 | C36: =TEXT(B36,"YYYYMM") -> 202605 | D36: Annya | E36: 房務部 | F36: 601 | G36: 床頭球燈：右邊不亮 | H36: 照明 | I36: IMG_1483.jpeg | J36: 空房 | K36: 燈具 | M36: 吳友仁 | O36: 待辦驗 | Q36: 已更換 | U36: 46149 | V36: 46153.533 | W36: 46148 | AA36: 0 | AG36: 0 | AI36: =VLOOKUP(A36,'4月明細'!B:B,1,0) -> #N/A
A37: In202605-051 | B37: 46148.687 | C37: =TEXT(B37,"YYYYMM") -> 202605 | D37: Annya | E37: 房務部 | F37: 601 | G37: 盥洗用品架需更換 | H37: 衛厠 | I37: IMG_1482.jpeg | J37: 空房 | K37: 淋浴間 | O37: 待修中 | U37: 46149 | V37: 46153.533 | W37: 46148 | X37: 46153 | AA37: 0 | AG37: 0 | AI37: =VLOOKUP(A37,'4月明細'!B:B,1,0) -> #N/A
A38: In202605-050 | B38: 46148.678 | C38: =TEXT(B38,"YYYYMM") -> 202605 | D38: Annya | E38: 房務部 | F38: 715 | G38: 通話到一半斷訊 | H38: 弱電 | J38: 空房 | K38: 電話 | M38: 吳友仁 | O38: 待辦驗 | Q38: 已修復 | U38: 46149 | V38: 46153.533 | W38: 46148 | AA38: 0 | AG38: 0 | AI38: =VLOOKUP(A38,'4月明細'!B:B,1,0) -> #N/A
A39: In202605-049 | B39: 46148.563 | C39: =TEXT(B39,"YYYYMM") -> 202605 | D39: 姿婷 | E39: 房務部 | F39: 507 | G39: 507續住 電視需手動開啟、遙控器無法開 房務員正在續掃 客人不在 謝謝 | H39: 會議設備 | J39: 緊急 | K39: 電視 | O39: 待修中 | U39: 46149 | V39: 46153.533 | W39: 46148 | X39: 46153 | Y39: 46153 | AA39: 0 | AG39: 0 | AI39: =VLOOKUP(A39,'4月明細'!B:B,1,0) -> #N/A
A40: In202605-048 | B40: 46148.546 | C40: =TEXT(B40,"YYYYMM") -> 202605 | D40: Eric | E40: 房務部 | F40: 806 | G40: 806 續住報修 電話沒有聲音，按了沒反應。 | H40: 弱電 | J40: 客人在房內 | K40: 電話 | M40: 吳友仁 | O40: 待辦驗 | Q40: 已修復 | U40: 46149 | V40: 46153.533 | W40: 46148 | AA40: 0 | AG40: 0 | AI40: =VLOOKUP(A40,'4月明細'!B:B,1,0) -> #N/A
...

Sheet 比對摘要
A1: 3.2 結案時間明細比對摘要 (2026年1月–5月，小型報修 total_fee=0)
A2: 月份 | B2: 結案數(Excel) | C2: 結案數(Portal) | D2: 一致 | E2: 總天數(Excel) | F2: 總天數(Portal) | G2: 一致 | H2: 均天數(Excel) | I2: 均天數(Portal) | J2: 一致
A3: 1月 | B3: ='1月明細'!B243 -> 240 | C3: 240 | D3: =IF(ABS(B3-C3)<=0.5,"✓","✗") -> ✓ | E3: ='1月明細'!D243 -> 365.98 | F3: 366 | G3: =IF(ABS(E3-F3)<=0.1,"✓","✗") -> ✓ | H3: ='1月明細'!F243 -> 1.5249167 | I3: 1.52 | J3: =IF(ABS(H3-I3)<=0.02,"✓","✗") -> ✓
A4: 2月 | B4: ='2月明細'!B233 -> 230 | C4: 230 | D4: =IF(ABS(B4-C4)<=0.5,"✓","✗") -> ✓ | E4: ='2月明細'!D233 -> 710.89 | F4: 710.9 | G4: =IF(ABS(E4-F4)<=0.1,"✓","✗") -> ✓ | H4: ='2月明細'!F233 -> 3.0908261 | I4: 3.09 | J4: =IF(ABS(H4-I4)<=0.02,"✓","✗") -> ✓
A5: 3月 | B5: ='3月明細'!B212 -> 209 | C5: 209 | D5: =IF(ABS(B5-C5)<=0.5,"✓","✗") -> ✓ | E5: ='3月明細'!D212 -> 483.07 | F5: 483.1 | G5: =IF(ABS(E5-F5)<=0.1,"✓","✗") -> ✓ | H5: ='3月明細'!F212 -> 2.3113397 | I5: 2.31 | J5: =IF(ABS(H5-I5)<=0.02,"✓","✗") -> ✓
A6: 4月 | B6: ='4月明細'!B124 -> 121 | C6: 121 | D6: =IF(ABS(B6-C6)<=0.5,"✓","✗") -> ✓ | E6: ='4月明細'!D124 -> 233.15 | F6: 233.2 | G6: =IF(ABS(E6-F6)<=0.1,"✓","✗") -> ✓ | H6: ='4月明細'!F124 -> 1.9268595 | I6: 1.93 | J6: =IF(ABS(H6-I6)<=0.02,"✓","✗") -> ✓
A7: 5月 | B7: ='5月明細'!B55 -> 52 | C7: 52 | D7: =IF(ABS(B7-C7)<=0.5,"✓","✗") -> ✓ | E7: ='5月明細'!D55 -> 194.37 | F7: 194.4 | G7: =IF(ABS(E7-F7)<=0.1,"✓","✗") -> ✓ | H7: ='5月明細'!F55 -> 3.7378846 | I7: 3.74 | J7: =IF(ABS(H7-I7)<=0.02,"✓","✗") -> ✓

Sheet 1月明細
A1: 序號 | B1: 報修單編號 | C1: 報修日期 | D1: 完工時間 | E1: 處理狀態 | F1: 維修費用 | G1: 委外費用 | H1: 合計費用 | I1: 結案天數 | J1: 備註
A2: 1 | B2: 20260101-001 | C2: 46023 | D2: 46024 | E2: 已辦驗 | F2: 0 | G2: 0 | H2: =F2+G2 -> 0 | I2: 1.17
A3: 2 | B3: 20260101-003 | C3: 46023 | D3: 46024 | E3: 已辦驗 | F3: 0 | G3: 0 | H3: =F3+G3 -> 0 | I3: 1.11
A4: 3 | B4: 20260101-004 | C4: 46023 | D4: 46024 | E4: 已辦驗 | F4: 0 | G4: 0 | H4: =F4+G4 -> 0 | I4: 1.1
A5: 4 | B5: 20260101-005 | C5: 46023 | D5: 46024 | E5: 已辦驗 | F5: 0 | G5: 0 | H5: =F5+G5 -> 0 | I5: 1.09
A6: 5 | B6: 20260101-006 | C6: 46023 | D6: 46024 | E6: 已辦驗 | F6: 0 | G6: 0 | H6: =F6+G6 -> 0 | I6: 1.06
A7: 6 | B7: 20260101-007 | C7: 46023 | D7: 46024 | E7: 已辦驗 | F7: 0 | G7: 0 | H7: =F7+G7 -> 0 | I7: 1.01
A8: 7 | B8: 20260101-008 | C8: 46023 | D8: 46024 | E8: 已辦驗 | F8: 0 | G8: 0 | H8: =F8+G8 -> 0 | I8: 0.92
A9: 8 | B9: 20260101-009 | C9: 46023 | D9: 46024 | E9: 已辦驗 | F9: 0 | G9: 0 | H9: =F9+G9 -> 0 | I9: 0.9
A10: 9 | B10: 20260101-011 | C10: 46023 | D10: 46024 | E10: 已辦驗 | F10: 0 | G10: 0 | H10: =F10+G10 -> 0 | I10: 0.86
A11: 10 | B11: 20260102-001 | C11: 46024 | D11: 46024 | E11: 已辦驗 | F11: 0 | G11: 0 | H11: =F11+G11 -> 0 | I11: 0.28
A12: 11 | B12: 20260102-002 | C12: 46024 | D12: 46024 | E12: 已辦驗 | F12: 0 | G12: 0 | H12: =F12+G12 -> 0 | I12: 0.16
A13: 12 | B13: 20260102-003 | C13: 46024 | D13: 46024 | E13: 已辦驗 | F13: 0 | G13: 0 | H13: =F13+G13 -> 0 | I13: 0.13
... A241: 240 | B241: 20260130-013 | C241: 46052 | D241: 46052 | E241: 已辦驗 | F241: 0 | G241: 0 | H241: =F241+G241 -> 0 | I241: 0.14
A242: 小計 | F242: =SUM(F2:F241) -> 0 | G242: =SUM(G2:G241) -> 0 | H242: =SUM(H2:H241) -> 0 | I242: =SUM(I2:I241) -> 365.98
A243: 結案數 | B243: =COUNTA(B2:B241) -> 240 | C243: 總天數 | D243: =SUM(I2:I241) -> 365.98 | E243: 平均天數 | F243: =AVERAGE(I2:I241) -> 1.5249167

Sheet 2月明細
A1: 序號 | B1: 報修單編號 | C1: 報修日期 | D1: 完工時間 | E1: 處理狀態 | F1: 維修費用 | G1: 委外費用 | H1: 合計費用 | I1: 結案天數 | J1: 備註
A2: 1 | B2: 20260101-012 | C2: 46023 | D2: 46055 | E2: 已辦驗 | F2: 0 | G2: 0 | H2: =F2+G2 -> 0 | I2: 31.63
A3: 2 | B3: 20260105-008 | C3: 46027 | D3: 46076 | E3: 已辦驗 | F3: 0 | G3: 0 | H3: =F3+G3 -> 0 | I3: 49.11
A4: 3 | B4: 20260110-010 | C4: 46032 | D4: 46062 | E4: 已辦驗 | F4: 0 | G4: 0 | H4: =F4+G4 -> 0 | I4: 29.98
A5: 4 | B5: 20260112-001 | C5: 46034 | D5: 46076 | E5: 已辦驗 | F5: 0 | G5: 0 | H5: =F5+G5 -> 0 | I5: 42.33
A6: 5 | B6: 20260112-002 | C6: 46034 | D6: 46076 | E6: 已辦驗 | F6: 0 | G6: 0 | H6: =F6+G6 -> 0 | I6: 42.33
A7: 6 | B7: 20260112-003 | C7: 46034 | D7: 46063 | E7: 已辦驗 | F7: 0 | G7: 0 | H7: =F7+G7 -> 0 | I7: 29.16
A8: 7 | B8: 20260112-004 | C8: 46034 | D8: 46063 | E8: 已辦驗 | F8: 0 | G8: 0 | H8: =F8+G8 -> 0 | I8: 29.16
A9: 8 | B9: 20260119-001 | C9: 46041 | D9: 46062 | E9: 已辦驗 | F9: 0 | G9: 0 | H9: =F9+G9 -> 0 | I9: 21.3
A10: 9 | B10: 20260130-010 | C10: 46044 | D10: 46057 | E10: 已辦驗 | F10: 0 | G10: 0 | H10: =F10+G10 -> 0 | I10: 12.97
A11: 10 | B11: 20260130-006 | C11: 46052 | D11: 46055 | E11: 已辦驗 | F11: 0 | G11: 0 | H11: =F11+G11 -> 0 | I11: 3.12
A12: 11 | B12: 20260130-008 | C12: 46052 | D12: 46055 | E12: 已辦驗 | F12: 0 | G12: 0 | H12: =F12+G12 -> 0 | I12: 3.1
A13: 12 | B13: 20260130-009 | C13: 46052 | D13: 46055 | E13: 已辦驗 | F13: 0 | G13: 0 | H13: =F13+G13 -> 0 | I13: 2.86
... A231: 230 | B231: 20260226-007 | C231: 46079 | D231: 46080 | E231: 已辦驗 | F231: 0 | G231: 0 | H231: =F231+G231 -> 0 | I231: 0.93
A232: 小計 | F232: =SUM(F2:F231) -> 0 | G232: =SUM(G2:G231) -> 0 | H232: =SUM(H2:H231) -> 0 | I232: =SUM(I2:I231) -> 710.89
A233: 結案數 | B233: =COUNTA(B2:B231) -> 230 | C233: 總天數 | D233: =SUM(I2:I231) -> 710.89 | E233: 平均天數 | F233: =AVERAGE(I2:I231) -> 3.0908261

Sheet 3月明細
A1: 序號 | B1: 報修單編號 | C1: 報修日期 | D1: 完工時間 | E1: 處理狀態 | F1: 維修費用 | G1: 委外費用 | H1: 合計費用 | I1: 結案天數 | J1: 備註
A2: 1 | B2: 20260130-017 | C2: 46052 | D2: 46098 | E2: 已辦驗 | F2: 0 | G2: 0 | H2: =F2+G2 -> 0 | I2: 45.91
A3: 2 | B3: 20260209-011 | C3: 46058 | D3: 46083 | E3: 已辦驗 | F3: 0 | G3: 0 | H3: =F3+G3 -> 0 | I3: 25.11
A4: 3 | B4: 20260208-003 | C4: 46061 | D4: 46098 | E4: 已辦驗 | F4: 0 | G4: 0 | H4: =F4+G4 -> 0 | I4: 37.01
A5: 4 | B5: 20260215-006 | C5: 46068 | D5: 46083 | E5: 已辦驗 | F5: 0 | G5: 0 | H5: =F5+G5 -> 0 | I5: 15.01
A6: 5 | B6: 20260215-012 | C6: 46068 | D6: 46083 | E6: 已辦驗 | F6: 0 | G6: 0 | H6: =F6+G6 -> 0 | I6: 14.72
A7: 6 | B7: 20260218-001 | C7: 46071 | D7: 46083 | E7: 已辦驗 | F7: 0 | G7: 0 | H7: =F7+G7 -> 0 | I7: 12.18
A8: 7 | B8: 20260218-008 | C8: 46071 | D8: 46083 | E8: 已辦驗 | F8: 0 | G8: 0 | H8: =F8+G8 -> 0 | I8: 11.88
A9: 8 | B9: 20260219-002 | C9: 46072 | D9: 46083 | E9: 已辦驗 | F9: 0 | G9: 0 | H9: =F9+G9 -> 0 | I9: 10.74
A10: 9 | B10: 20260220-002 | C10: 46073 | D10: 46083 | E10: 已辦驗 | F10: 0 | G10: 0 | H10: =F10+G10 -> 0 | I10: 10.57
A11: 10 | B11: 20260223-023 | C11: 46076 | D11: 46083 | E11: 已辦驗 | F11: 0 | G11: 0 | H11: =F11+G11 -> 0 | I11: 7.08
A12: 11 | B12: 20260223-047 | C12: 46076 | D12: 46083 | E12: 已辦驗 | F12: 0 | G12: 0 | H12: =F12+G12 -> 0 | I12: 7.06
A13: 12 | B13: 20260223-049 | C13: 46076 | D13: 46083 | E13: 已辦驗 | F13: 0 | G13: 0 | H13: =F13+G13 -> 0 | I13: 7.06
... A210: 209 | B210: 20260331-002 | C210: 46112 | D210: 46112 | E210: 已辦驗 | F210: 0 | G210: 0 | H210: =F210+G210 -> 0 | I210: 0.03
A211: 小計 | F211: =SUM(F2:F210) -> 0 | G211: =SUM(G2:G210) -> 0 | H211: =SUM(H2:H210) -> 0 | I211: =SUM(I2:I210) -> 483.07
A212: 結案數 | B212: =COUNTA(B2:B210) -> 209 | C212: 總天數 | D212: =SUM(I2:I210) -> 483.07 | E212: 平均天數 | F212: =AVERAGE(I2:I210) -> 2.3113397

Sheet 4月明細
A1: 序號 | B1: 報修單編號 | C1: 報修日期 | D1: 完工時間 | E1: 處理狀態 | F1: 維修費用 | G1: 委外費用 | H1: 合計費用 | I1: 結案天數 | J1: 備註
A2: 1 | B2: 20260309-004 | C2: 46090 | D2: 46125 | E2: 已辦驗 | F2: 0 | G2: 0 | H2: =F2+G2 -> 0 | I2: 35.18
A3: 2 | B3: 20260322-005 | C3: 46103 | D3: 46122 | E3: 已辦驗 | F3: 0 | G3: 0 | H3: =F3+G3 -> 0 | I3: 19.04
A4: 3 | B4: 20260325-002 | C4: 46106 | D4: 46122 | E4: 已辦驗 | F4: 0 | G4: 0 | H4: =F4+G4 -> 0 | I4: 15.62
A5: 4 | B5: 20260329-002 | C5: 46110 | D5: 46125 | E5: 已辦驗 | F5: 0 | G5: 0 | H5: =F5+G5 -> 0 | I5: 14.92
A6: 5 | B6: 20260401-001 | C6: 46113 | D6: 46113 | E6: 已辦驗 | F6: 0 | G6: 0 | H6: =F6+G6 -> 0 | I6: 0.33
A7: 6 | B7: 20260401-002 | C7: 46113 | D7: 46113 | E7: 已辦驗 | F7: 0 | G7: 0 | H7: =F7+G7 -> 0 | I7: 0.26
A8: 7 | B8: 20260401-003 | C8: 46113 | D8: 46113 | E8: 已辦驗 | F8: 0 | G8: 0 | H8: =F8+G8 -> 0 | I8: 0.21
A9: 8 | B9: 20260401-004 | C9: 46113 | D9: 46122 | E9: 已辦驗 | F9: 0 | G9: 0 | H9: =F9+G9 -> 0 | I9: 8.96
A10: 9 | B10: 20260401-005 | C10: 46113 | D10: 46113 | E10: 已辦驗 | F10: 0 | G10: 0 | H10: =F10+G10 -> 0 | I10: 0.18
A11: 10 | B11: 20260401-006 | C11: 46113 | D11: 46113 | E11: 已辦驗 | F11: 0 | G11: 0 | H11: =F11+G11 -> 0 | I11: 0.18
A12: 11 | B12: 20260401-007 | C12: 46113 | D12: 46125 | E12: 已辦驗 | F12: 0 | G12: 0 | H12: =F12+G12 -> 0 | I12: 11.7
A13: 12 | B13: 20260402-002 | C13: 46114 | D13: 46114 | E13: 已辦驗 | F13: 0 | G13: 0 | H13: =F13+G13 -> 0 | I13: 0.28
... A122: 121 | B122: In202604-081 | C122: 46139 | D122: 46140 | E122: 已辦驗 | F122: 0 | G122: 0 | H122: =F122+G122 -> 0 | I122: 0.83
A123: 小計 | F123: =SUM(F2:F122) -> 0 | G123: =SUM(G2:G122) -> 0 | H123: =SUM(H2:H122) -> 0 | I123: =SUM(I2:I122) -> 233.15
A124: 結案數 | B124: =COUNTA(B2:B122) -> 121 | C124: 總天數 | D124: =SUM(I2:I122) -> 233.15 | E124: 平均天數 | F124: =AVERAGE(I2:I122) -> 1.9268595

Sheet 5月明細
A1: 序號 | B1: 報修單編號 | C1: 報修日期 | D1: 完工時間 | E1: 處理狀態 | F1: 維修費用 | G1: 委外費用 | H1: 合計費用 | I1: 結案天數 | J1: 備註
A2: 1 | B2: In202604-075 | C2: 46139 | D2: 46147 | E2: 已辦驗 | F2: 0 | G2: 0 | H2: =F2+G2 -> 0 | I2: 8.05
A3: 2 | B3: In202604-077 | C3: 46139 | D3: 46147 | E3: 已辦驗 | F3: 0 | G3: 0 | H3: =F3+G3 -> 0 | I3: 7.94
A4: 3 | B4: In202604-079 | C4: 46139 | D4: 46147 | E4: 已辦驗 | F4: 0 | G4: 0 | H4: =F4+G4 -> 0 | I4: 7.91
A5: 4 | B5: In202604-080 | C5: 46139 | D5: 46147 | E5: 已辦驗 | F5: 0 | G5: 0 | H5: =F5+G5 -> 0 | I5: 7.91
A6: 5 | B6: In202604-082 | C6: 46139 | D6: 46147 | E6: 已辦驗 | F6: 0 | G6: 0 | H6: =F6+G6 -> 0 | I6: 7.88
A7: 6 | B7: In202604-083 | C7: 46140 | D7: 46147 | E7: 已辦驗 | F7: 0 | G7: 0 | H7: =F7+G7 -> 0 | I7: 7.01
A8: 7 | B8: In202604-084 | C8: 46140 | D8: 46147 | E8: 已辦驗 | F8: 0 | G8: 0 | H8: =F8+G8 -> 0 | I8: 6.99
A9: 8 | B9: In202604-086 | C9: 46140 | D9: 46147 | E9: 已辦驗 | F9: 0 | G9: 0 | H9: =F9+G9 -> 0 | I9: 6.99
A10: 9 | B10: In202604-085 | C10: 46140 | D10: 46147 | E10: 已辦驗 | F10: 0 | G10: 0 | H10: =F10+G10 -> 0 | I10: 6.98
A11: 10 | B11: In202604-092 | C11: 46141 | D11: 46148 | E11: 已辦驗 | F11: 0 | G11: 0 | H11: =F11+G11 -> 0 | I11: 7.13
A12: 11 | B12: In202604-093 | C12: 46141 | D12: 46147 | E12: 已辦驗 | F12: 0 | G12: 0 | H12: =F12+G12 -> 0 | I12: 5.84
A13: 12 | B13: In202604-096 | C13: 46141 | D13: 46147 | E13: 已辦驗 | F13: 0 | G13: 0 | H13: =F13+G13 -> 0 | I13: 5.81
... A53: 52 | B53: In202605-047 | C53: 46148 | D53: 46148 | E53: 已辦驗 | F53: 0 | G53: 0 | H53: =F53+G53 -> 0 | I53: 0.24
A54: 小計 | F54: =SUM(F2:F53) -> 0 | G54: =SUM(G2:G53) -> 0 | H54: =SUM(H2:H53) -> 0 | I54: =SUM(I2:I53) -> 194.37
A55: 結案數 | B55: =COUNTA(B2:B53) -> 52 | C55: 總天數 | D55: =SUM(I2:I53) -> 194.37 | E55: 平均天數 | F55: =AVERAGE(I2:I53) -> 3.7378846
