Workbook

Sheet 4.1 報修統計
A1: 春大直工務部 ｜ 2026 年度報修統計
A2: 統計項目 | B2: 1 月 | C2: 2 月 | D2: 3 月 | E2: 4 月 | F2: 5 月 | G2: 6 月 | H2: 7 月 | I2: 8 月 | J2: 9 月 | K2: 10 月 | L2: 11 月 | M2: 12 月 | N2: 合計
A3: ① 上月累計未完成項目數 | B3: 3 | C3: 5 | D3: 3 | E3: 10 | F3: 4 | G3: 4 | H3: 4 | I3: 4 | J3: 4 | K3: 4 | L3: 4 | M3: 4 | N3: =SUM(B3,C3,D3,E3,F3,G3,H3,I3,J3,K3,L3,M3) -> 53
A4: ② 上月未完成，本月結案數 | B4: 3 | C4: 3 | D4: 1 | E4: 10 | F4: 0 | G4: 0 | H4: 0 | I4: 0 | J4: 0 | K4: 0 | L4: 0 | M4: 0 | N4: =SUM(B4,C4,D4,E4,F4,G4,H4,I4,J4,K4,L4,M4) -> 17 | Q4: =59+1911 -> 1970
A5: ③ 上月累計完成數（① - ②） | B5: 0 | C5: 2 | D5: 2 | E5: 0 | F5: 4 | G5: 4 | H5: 4 | I5: 4 | J5: 4 | K5: 4 | L5: 4 | M5: 4 | N5: =SUM(B5,C5,D5,E5,F5,G5,H5,I5,J5,K5,L5,M5) -> 36
A6: ④ 累計項目完成率（%） | B6: 0.848 | C6: 0.919 | D6: 0.778 | E6: 0.956 | F6: 0.956 | G6: 0.956 | H6: 0.956 | I6: 0.956 | J6: 0.956 | K6: 0.956 | L6: 0.956 | M6: 0.956 | N6: —
A7: ⑤ 本月報修項目數 | B7: 26 | C7: 4 | D7: 8 | E7: 45 | F7: 0 | G7: 0 | H7: 0 | I7: 0 | J7: 0 | K7: 0 | L7: 0 | M7: 0 | N7: =SUM(B7,C7,D7,E7,F7,G7,H7,I7,J7,K7,L7,M7) -> 83
A8: ⑥ 本月報修項目完成數 | B8: 21 | C8: 3 | D8: 0 | E8: 41 | F8: 0 | G8: 0 | H8: 0 | I8: 0 | J8: 0 | K8: 0 | L8: 0 | M8: 0 | N8: =SUM(B8,C8,D8,E8,F8,G8,H8,I8,J8,K8,L8,M8) -> 65
A9: ⑦ 本月未完成數 | B9: 5 | C9: 1 | D9: 8 | E9: 4 | F9: 0 | G9: 0 | H9: 0 | I9: 0 | J9: 0 | K9: 0 | L9: 0 | M9: 0 | N9: =SUM(B9,C9,D9,E9,F9,G9,H9,I9,J9,K9,L9,M9) -> 18
A10: ⑧ 本月報修項目完成率（%） | B10: 0.808 | C10: 0.75 | D10: 0 | E10: 0.911 | F10: — | G10: — | H10: — | I10: — | J10: — | K10: — | L10: — | M10: — | N10: —
A11: 平均結案天數（天） | B11: 2.7 | C11: 1.9 | D11: — | E11: 7.6 | F11: — | G11: — | H11: — | I11: — | J11: — | K11: — | L11: — | M11: — | N11: =AVERAGE(B11,C11,E11) -> 4.0666667
A13: 資料來源：春大直 - 報修清單總表20260429.xlsx ｜ 統計年度：2026 ｜ 完成判定：完工時間不為空 或 狀態/處理狀況∈{結案、已辦驗…} ｜ ③ = ①－②

Sheet 原始數據
A1: 報修編號 | B1: 報修單位 | C1: 報修日期 | D1: 標題 | E1: 報修類型 | F1: 發生樓層 | G1: 問題狀態 | H1: 狀態 | I1: 完工時間 | J1: 結案時間 | K1: 委外費用 | L1: 維修費用 | M1: 扣款費用 | N1: 維修工時(天) | O1: 是否結案 | P1: 報修年 | Q1: 報修月 | R1: 結案年 | S1: 結案月 | T1: 統計年(stat_year) | U1: 統計月(stat_month) | V1: 結案天數(close_days)
A2: 202604-045 | B2: 營業 | C2: 2026-04-28 00:00 | D2: 5/1，二快閃櫃設櫃 | E2: 公區 | F2: 1F | O2: ✗ | P2: 2026 | Q2: 4 | T2: 2026 | U2: 4
A3: 202604-044 | B3: 服務台 | C3: 2026-04-27 00:00 | D3: 3樓女廁進來第二間馬桶不通 | E3: 衛厠 | F3: 3F | H3: 結案 | I3: 2026-04-29 09:03 | J3: 2026-04-29 09:03 | M3: 0 | O3: ✓ | P3: 2026 | Q3: 4 | R3: 2026 | S3: 4 | T3: 2026 | U3: 4 | V3: 2
A4: 202604-043 | B4: 管理 | C4: 2026-04-27 00:00 | D4: 2026上半年消防缺改善 | E4: 消防 | I4: 2026-04-28 10:13 | L4: 2026上半年消防缺改善 | O4: ✗ | P4: 2026 | Q4: 4 | T4: 2026 | U4: 4
A5: 20260400072 | B5: 服務台 | C5: 2026-04-27 00:00 | D5: 漢堡世家電子鎖沒電(測試單，勿理會) | E5: 機電 | F5: 1F | H5: 結案 | I5: 2026-04-27 13:55 | J5: 2026-04-27 11:58 | O5: ✓ | P5: 2026 | Q5: 4 | R5: 2026 | S5: 4 | T5: 2026 | U5: 4 | V5: 0
A6: 202604-041 | B6: 服務台 | C6: 2026-04-25 00:00 | D6: B2水管漏水 | E6: 給&排水 | F6: B2F | H6: 結案 | I6: 2026-04-28 17:30 | J6: 2026-04-27 12:05 | M6: 0 | O6: ✓ | P6: 2026 | Q6: 4 | R6: 2026 | S6: 4 | T6: 2026 | U6: 4 | V6: 2
A7: 202604-040 | B7: 服務台 | C7: 2026-04-25 00:00 | D7: 漢堡世家電子鎖沒電 | E7: 機電 | F7: 1F | H7: 結案 | I7: 2026-04-28 17:23 | J7: 2026-04-27 11:58 | M7: 0 | O7: ✓ | P7: 2026 | Q7: 4 | R7: 2026 | S7: 4 | T7: 2026 | U7: 4 | V7: 2
A8: 202604-039 | B8: 服務台 | C8: 2026-04-25 00:00 | D8: 泰市場發現後場臥櫃冰箱沒有電力 | E8: 凍&藏類設備 | F8: 4F | H8: 結案 | I8: 2026-04-28 17:24 | J8: 2026-04-27 12:17 | M8: 0 | O8: ✓ | P8: 2026 | Q8: 4 | R8: 2026 | S8: 4 | T8: 2026 | U8: 4 | V8: 2
A9: 202604-038 | B9: 服務台 | C9: 2026-04-25 00:00 | D9: 瞞著爹前天井柱燈閃爍 | E9: 專櫃 | F9: 1F | H9: 結案 | I9: 2026-04-28 17:25 | J9: 2026-04-27 11:57 | L9: 137 | M9: 137 | O9: ✓ | P9: 2026 | Q9: 4 | R9: 2026 | S9: 4 | T9: 2026 | U9: 4 | V9: 2
A10: 202604-037 | B10: 營業 | C10: 2026-04-23 00:00 | D10: 1f 牪肉舖 水管破洞漏水，已購買新水管，請工務安裝，需收費 | E10: 給&排水 | F10: 1F | G10: 急單 | H10: 結案 | I10: 2026-04-29 08:25 | J10: 2026-04-24 08:17 | M10: 800 | N10: 1 | O10: ✓ | P10: 2026 | Q10: 4 | R10: 2026 | S10: 4 | T10: 2026 | U10: 4 | V10: 1
A11: 202604-036 | B11: 服務台 | C11: 2026-04-23 00:00 | D11: 4樓愛心廁所_x000D_ 紅色按鈕加裝壓克力盒 | E11: 衛厠 | F11: 4F | I11: 2026-04-23 16:53 | O11: ✗ | P11: 2026 | Q11: 4 | T11: 2026 | U11: 4
A12: 202604-035 | B12: 營業 | C12: 2026-04-23 00:00 | D12: 戶外餐車--旨燕拉麵，電子鎖電力不足 | E12: 專櫃 | F12: 1F | I12: 2026-04-24 11:46 | O12: ✗ | P12: 2026 | Q12: 4 | T12: 2026 | U12: 4
A13: 1129 | B13: 管理 | C13: 2025-11-25 15:32 | D13: 第一階段和第二階段: 汙水管路通管工程 (急單廠商11/26進場) | E13: 給排水 | H13: 結案 | I13: 2025-11-29 19:53 | J13: 2025-12-04 08:27 | K13: 69300 | M13: 146193 | O13: ✓ | P13: 2025 | Q13: 11 | R13: 2025 | S13: 12 | T13: 2025 | U13: 12 | V13: 9
A14: 1097 | B14: 營業 | C14: 2025-10-21 15:51 | D14: 2F 燒鳥新增排煙濾網工程 | E14: 專櫃 | F14: 2F | H14: 結案 | I14: 2025-12-11 13:15 | J14: 2025-12-26 11:18 | K14: 30000 | M14: 50400 | O14: ✓ | P14: 2025 | Q14: 10 | R14: 2025 | S14: 12 | T14: 2025 | U14: 12 | V14: 66
A15: 202604-034 | B15: 工務 | C15: 2026-04-22 00:00 | D15: 植福路3面輸出牆的格柵天花板，需要新增6個電線接口 | E15: 商場公區 | F15: 1F | I15: 2026-04-28 09:19 | O15: ✗ | P15: 2026 | Q15: 4 | T15: 2026 | U15: 4
A16: 202604-033 | B16: 工務 | C16: 2026-04-22 00:00 | D16: 植福路樂群三路口三角招牌電源插座安裝 | I16: 2026-04-28 09:18 | O16: ✗ | P16: 2026 | Q16: 4 | T16: 2026 | U16: 4
A17: 1236 | B17: 管理 | C17: 2026-02-11 12:57 | D17: B2F截油槽排水主幹管堵塞 | E17: 給排水 | F17: B2F | H17: 結案 | I17: 2026-02-13 13:47 | J17: 2026-02-26 10:05 | K17: 15750 | O17: ✓ | P17: 2026 | Q17: 2 | R17: 2026 | S17: 2 | T17: 2026 | U17: 2 | V17: 15
A18: 1232 | B18: 服務台 | C18: 2026-02-09 20:30 | D18: 一樓回收區無法排水、堵塞 | E18: 給排水 | H18: 結案 | I18: 2026-02-11 17:52 | J18: 2026-02-23 08:48 | O18: ✓ | P18: 2026 | Q18: 2 | R18: 2026 | S18: 2 | T18: 2026 | U18: 2 | V18: 14
A19: 1229 | B19: 服務台 | C19: 2026-02-07 16:15 | D19: 泰市場開放區排水管堵塞 | H19: 結案 | I19: 2026-02-09 09:32 | J19: 2026-02-11 16:39 | M19: 1260 | O19: ✓ | P19: 2026 | Q19: 2 | R19: 2026 | S19: 2 | T19: 2026 | U19: 2 | V19: 4
A20: 1222 | B20: 服務台 | C20: 2026-01-31 14:30 | D20: 4樓泰市場瓦斯警報不定時發報請協助調整 | H20: 結案 | I20: 2026-02-04 17:34 | J20: 2026-02-11 16:40 | O20: ✓ | P20: 2026 | Q20: 1 | R20: 2026 | S20: 2 | T20: 2026 | U20: 2 | V20: 11
A21: 1221 | B21: 營業 | C21: 2026-01-30 18:04 | D21: b梯員工出入口安全門地鉸鍊無法回𢓴 | F21: 1F | H21: 結案 | I21: 2026-01-31 12:46 | J21: 2026-02-02 08:41 | O21: ✓ | P21: 2026 | Q21: 1 | R21: 2026 | S21: 2 | T21: 2026 | U21: 2 | V21: 3
A22: 1220 | B22: 管理 | C22: 2026-01-30 09:45 | D22: B1辦公室前洗手台排水管漏水 | F22: B1F | H22: 結案 | I22: 2026-01-31 12:46 | J22: 2026-02-26 10:06 | O22: ✓ | P22: 2026 | Q22: 1 | R22: 2026 | S22: 2 | T22: 2026 | U22: 2 | V22: 27
A23: 1215 | B23: 服務台 | C23: 2026-01-29 12:29 | D23: B3,239車位前投射燈不亮 | H23: 結案 | I23: 2026-01-31 14:25 | J23: 2026-02-02 08:41 | L23: 620 | O23: ✓ | P23: 2026 | Q23: 1 | R23: 2026 | S23: 2 | T23: 2026 | U23: 2 | V23: 4
A24: 1214 | B24: 服務台 | C24: 2026-01-29 11:01 | D24: 固德威天花板水管漏水 | H24: 結案 | I24: 2026-01-31 16:08 | J24: 2026-02-02 08:43 | O24: ✓ | P24: 2026 | Q24: 1 | R24: 2026 | S24: 2 | T24: 2026 | U24: 2 | V24: 4
A25: 1213 | B25: 服務台 | C25: 2026-01-29 10:54 | D25: 傻滷天井柱燈不亮 | H25: 結案 | I25: 2026-01-30 11:25 | J25: 2026-02-02 08:43 | L25: 137 | O25: ✓ | P25: 2026 | Q25: 1 | R25: 2026 | S25: 2 | T25: 2026 | U25: 2 | V25: 4
A26: 1207 | B26: 營業 | C26: 2026-01-22 21:05 | D26: 2/5~2/6租賃油壓車 | E26: 商場公區 | F26: B1F | H26: 結案 | I26: 2026-02-04 17:36 | J26: 2026-02-11 16:40 | L26: 9450 | O26: ✓ | P26: 2026 | Q26: 1 | R26: 2026 | S26: 2 | T26: 2026 | U26: 2 | V26: 20
A27: 1188 | B27: 管理 | C27: 2026-01-08 10:22 | D27: B1回收室廚餘冰箱溫度異常 | E27: 後勤空間 | F27: B1F | H27: 結案 | I27: 2026-01-25 16:16 | J27: 2026-02-26 10:06 | O27: ✓ | P27: 2026 | Q27: 1 | R27: 2026 | S27: 2 | T27: 2026 | U27: 2 | V27: 49
A28: 1182 | B28: 行銷 | C28: 2026-01-05 14:46 | D28: 1/21前完成 - 戶外九宮格燈箱燈箱片安裝 | H28: 結案 | I28: 2026-02-11 17:55 | J28: 2026-02-13 12:33 | K28: 9000 | O28: ✓ | P28: 2026 | Q28: 1 | R28: 2026 | S28: 2 | T28: 2026 | U28: 2 | V28: 39
A29: 1210 | B29: 服務台 | C29: 2026-01-25 15:22 | D29: B1漏水 | H29: 結案 | I29: 2026-01-25 16:10 | J29: 2026-01-29 14:17 | O29: ✓ | P29: 2026 | Q29: 1 | R29: 2026 | S29: 1 | T29: 2026 | U29: 1 | V29: 4
A30: 1209 | B30: 服務台 | C30: 2026-01-24 18:15 | D30: B2,162車位上方集水盤漏水 | H30: 結案 | I30: 2026-01-25 16:12 | J30: 2026-01-29 14:17 | O30: ✓ | P30: 2026 | Q30: 1 | R30: 2026 | S30: 1 | T30: 2026 | U30: 1 | V30: 5
A31: 1203 | B31: 管理 | C31: 2026-01-19 09:55 | D31: B梯員工出入口-1F安全門無法自動回復 | E31: 消防 | F31: 1F | H31: 結案 | I31: 2026-01-21 09:59 | J31: 2026-01-23 17:06 | O31: ✓ | P31: 2026 | Q31: 1 | R31: 2026 | S31: 1 | T31: 2026 | U31: 1 | V31: 4
A32: 1201 | B32: 營業 | C32: 2026-01-17 19:18 | D32: 1樓大門門把鬆脫（近富錦樹） | E32: 商場公區 | F32: 1F | H32: 結案 | I32: 2026-01-20 14:41 | J32: 2026-01-23 17:06 | O32: ✓ | P32: 2026 | Q32: 1 | R32: 2026 | S32: 1 | T32: 2026 | U32: 1 | V32: 6
A33: 1200 | B33: 服務台 | C33: 2026-01-17 11:52 | D33: B1預備車位（發電機房外）天花板吸頂燈不亮 | H33: 結案 | I33: 2026-01-21 11:18 | J33: 2026-01-23 17:06 | L33: 294 | O33: ✓ | P33: 2026 | Q33: 1 | R33: 2026 | S33: 1 | T33: 2026 | U33: 1 | V33: 6
A34: 1197 | B34: 服務台 | C34: 2026-01-12 21:30 | D34: 4樓男廁一顆燈泡壞掉 | F34: 4F | H34: 結案 | I34: 2026-04-27 15:00 | J34: 2026-01-23 17:07 | O34: ✓ | P34: 2026 | Q34: 1 | R34: 2026 | S34: 1 | T34: 2026 | U34: 1 | V34: 11
A35: 1196 | B35: 服務台 | C35: 2026-01-11 12:03 | D35: 車道安全上方燈開了20分鐘才會亮 | H35: 結案 | I35: 2026-01-22 15:41 | J35: 2026-01-23 17:07 | L35: 520 | O35: ✓ | P35: 2026 | Q35: 1 | R35: 2026 | S35: 1 | T35: 2026 | U35: 1 | V35: 12
A36: 1195 | B36: 服務台 | C36: 2026-01-09 11:56 | D36: B2,158車位旁日光燈不亮 | H36: 結案 | I36: 2026-01-09 15:19 | J36: 2026-01-12 08:15 | L36: 74 | O36: ✓ | P36: 2026 | Q36: 1 | R36: 2026 | S36: 1 | T36: 2026 | U36: 1 | V36: 3
A37: 1193 | B37: 工務 | C37: 2026-01-08 12:31 | D37: 1-03 前臨時櫃位電力配置 | E37: 商場公區 | F37: 1F | H37: 結案 | I37: 2026-01-09 14:45 | J37: 2026-01-12 08:16 | L37: 263 | O37: ✓ | P37: 2026 | Q37: 1 | R37: 2026 | S37: 1 | T37: 2026 | U37: 1 | V37: 4
A38: 1189 | B38: 管理 | C38: 2026-01-08 10:28 | D38: 垃圾廚餘間電錶異常 | E38: 後勤空間 | F38: B1F | H38: 結案 | I38: 2026-01-15 12:59 | J38: 2026-01-16 08:04 | K38: 500 | O38: ✓ | P38: 2026 | Q38: 1 | R38: 2026 | S38: 1 | T38: 2026 | U38: 1 | V38: 8
A39: 1186 | B39: 服務台 | C39: 2026-01-07 11:31 | D39: SAKEMARU燈罩燈泡不亮 | H39: 結案 | I39: 2026-01-07 11:34 | J39: 2026-01-09 10:42 | L39: 137 | O39: ✓ | P39: 2026 | Q39: 1 | R39: 2026 | S39: 1 | T39: 2026 | U39: 1 | V39: 2
A40: 1185 | B40: 管理 | C40: 2026-01-05 18:46 | D40: B1回收室水槽漏水 | E40: 後勤空間 | F40: B1F | H40: 結案 | I40: 2026-01-07 10:58 | J40: 2026-01-09 10:42 | O40: ✓ | P40: 2026 | Q40: 1 | R40: 2026 | S40: 1 | T40: 2026 | U40: 1 | V40: 4
...

Sheet 工作表1
A1: 報修編號 | B1: 標題 | C1: 樓層 | D1: 報修時間 | E1: 狀態 | F1: 結案天數 | G1: 費用合計 | H1: 扣款專櫃 | I1: 詳情
A2: 202604-028 | B2: B1樓 紙箱回收籠車上方消防設備自天花板掉落 | C2: B1F | D2: 46131.899 | E2: - | F2: - | G2: - | K2: =VLOOKUP(A2,原始數據!A:A,1,0) -> 202604-028
A3: 202604-027 | B3: 請安排5月份 各專櫃汙水管通管工程 | D3: 46131.822 | E3: - | F3: - | G3: - | K3: =VLOOKUP(A3,原始數據!A:A,1,0) -> 202604-027
A4: 202604-026 | B4: 2樓殘障廁所 沒水 有臭味 請緊急維修 | C4: 2F | D4: 46131.613 | E4: 已辦驗 | F4: 4.7 天 | G4: 38 | K4: =VLOOKUP(A4,原始數據!A:A,1,0) -> 202604-026
A5: 202604-025 | B5: 1F 回收台(靠貨梯旁)門片故障需修理 | C5: 1F | D5: 46130.85 | E5: 已辦驗 | F5: 5.5 天 | G5: - | K5: =VLOOKUP(A5,原始數據!A:A,1,0) -> 202604-025
A6: 202604-024 | B6: 2樓下一樓手扶梯斷斷續續的停止 | C6: 2F | D6: 46130.742 | E6: 已辦驗 | F6: 4.8 天 | G6: - | K6: =VLOOKUP(A6,原始數據!A:A,1,0) -> 202604-024
A7: 202604-023 | B7: 1樓環狀燈泡閃爍，salud、果汁店 | C7: 1F | D7: 46129.454 | E7: 已辦驗 | F7: 7.0 天 | G7: 142 | K7: =VLOOKUP(A7,原始數據!A:A,1,0) -> 202604-023
A8: 202604-022 | B8: 桌子高低 | C8: 1F | D8: 46128.83 | E8: - | F8: - | G8: - | K8: =VLOOKUP(A8,原始數據!A:A,1,0) -> 202604-022
A9: 202604-021 | B9: 二樓女廁第二間馬桶蓋掉落 請維修處理 | C9: 2F | D9: 46128.662 | E9: 已辦驗 | F9: 4.7 天 | G9: - | K9: =VLOOKUP(A9,原始數據!A:A,1,0) -> 202604-021
A10: 202604-020 | B10: 2樓女廁第2間馬桶蓋壞了 | C10: 2F | D10: 46127.702 | E10: 已辦驗 | F10: 7.9 天 | G10: - | K10: =VLOOKUP(A10,原始數據!A:A,1,0) -> 202604-020
A11: 202604-019 | B11: 泰市場煎魚台上方偵煙器移位 | C11: 4F | D11: 46127.49 | E11: 待辦驗 | F11: 12.0 天 | G11: 1600 | H11: 泰市場 | K11: =VLOOKUP(A11,原始數據!A:A,1,0) -> 202604-019
A12: 202604-018 | B12: 2樓男廁第3間馬桶蓋壞了 | C12: 2F | D12: 46125.628 | E12: 已辦驗 | F12: 7.8 天 | G12: - | K12: =VLOOKUP(A12,原始數據!A:A,1,0) -> 202604-018
A13: 202604-017 | B13: 2樓女廁第2間門鎖掉落 | C13: 2F | D13: 46125.432 | E13: 已辦驗 | F13: 8.0 天 | G13: - | K13: =VLOOKUP(A13,原始數據!A:A,1,0) -> 202604-017
A14: 202604-016 | B14: 二下一手扶梯不定時停止運作，代碼5 | D14: 46124.827 | E14: 已辦驗 | F14: 8.6 天 | G14: - | K14: =VLOOKUP(A14,原始數據!A:A,1,0) -> 202604-016
A15: 202604-015 | B15: 商場容留計數器未作動 | C15: 1F | D15: 46124.825 | E15: 已辦驗 | F15: 9.5 天 | G15: - | K15: =VLOOKUP(A15,原始數據!A:A,1,0) -> 202604-015
A16: 202604-014 | B16: 側門上面的鋁合金不見 | C16: 1F | D16: 46122.688 | E16: 處理中 | F16: 2.8 天 | G16: - | K16: =VLOOKUP(A16,原始數據!A:A,1,0) -> 202604-014
A17: 202604-013 | B17: 小後苑植福路旁有野草雜草沒有清除 | C17: 1F | D17: 46122.687 | E17: 已辦驗 | F17: 10.7 天 | G17: - | K17: =VLOOKUP(A17,原始數據!A:A,1,0) -> 202604-013
A18: 202604-012 | B18: 植福路上南花圃內的固定鋼索要移除 | C18: 1F | D18: 46122.685 | E18: 待辦驗 | F18: 16.8 天 | G18: - | K18: =VLOOKUP(A18,原始數據!A:A,1,0) -> 202604-012
A19: 202604-011 | B19: 植福路上照樹燈的電線外露 | C19: 1F | D19: 46122.684 | E19: 委外處理 | F19: 17.7 天 | G19: - | K19: =VLOOKUP(A19,原始數據!A:A,1,0) -> 202604-011
A20: 202604-010 | B20: 植福路側門旁花台內水管凌亂及戶外電箱損壞 | C20: 1F | D20: 46122.683 | E20: 待辦驗 | F20: 16.9 天 | G20: - | K20: =VLOOKUP(A20,原始數據!A:A,1,0) -> 202604-010
A21: 202604-009 | B21: 植福路上花舖的固定鋼索圈要移除 | C21: 1F | D21: 46122.681 | E21: 處理中 | F21: 13.1 天 | G21: - | K21: =VLOOKUP(A21,原始數據!A:A,1,0) -> 202604-009
A22: 202604-008 | B22: 剪鋼索及木頭支架 | C22: 1F | D22: 46122.677 | E22: 處理中 | F22: 1.1 天 | G22: - | K22: =VLOOKUP(A22,原始數據!A:A,1,0) -> 202604-008
A23: 202604-007 | B23: 傻雞前天井柱燈不亮 | C23: 1F | D23: 46122.457 | E23: 已辦驗 | F23: 3.0 天 | G23: 137 | K23: =VLOOKUP(A23,原始數據!A:A,1,0) -> 202604-007
A24: 202604-006 | B24: 三樓女廁洗手檯投照燈故障 | C24: 3F | D24: 46119.581 | E24: 已辦驗 | F24: 19.9 天 | G24: 499 | K24: =VLOOKUP(A24,原始數據!A:A,1,0) -> 202604-006
A25: 202604-005 | B25: 一樓戶外woolloomooloo 旁垃圾桶，玻璃瓶桶脫落 | D25: 46118.469 | E25: 已辦驗 | F25: 14.9 天 | G25: - | K25: =VLOOKUP(A25,原始數據!A:A,1,0) -> 202604-005
A26: 202604-004 | B26: 瞞著爹前天井柱燈不亮 | D26: 46117.438 | E26: 已辦驗 | F26: 11.9 天 | G26: 137 | K26: =VLOOKUP(A26,原始數據!A:A,1,0) -> 202604-004
A27: 202604-003 | B27: B4,356號停車格上方水管滴水 | D27: 46116.89 | E27: 已辦驗 | F27: 16.5 天 | G27: - | K27: =VLOOKUP(A27,原始數據!A:A,1,0) -> 202604-003
A28: 202604-002 | B28: 1F戶外餐車漢堡世家新增切肉機需求電源 3相220V | C28: 1F | D28: 46114.635 | E28: 已辦驗 | F28: 7.8 天 | G28: - | K28: =VLOOKUP(A28,原始數據!A:A,1,0) -> 202604-002
A29: 202604-001 | B29: 1樓側門的地錬故障 | C29: 1F | D29: 46114.477 | E29: 已辦驗 | F29: 21.9 天 | G29: 31300 | K29: =VLOOKUP(A29,原始數據!A:A,1,0) -> 202604-001
A30: 202604-029 | B30: 牪牛肉的冰箱漏水 | C30: 1F | D30: 46132.445 | E30: 已辦驗 | F30: 3.9 天 | G30: - | K30: =VLOOKUP(A30,原始數據!A:A,1,0) -> 202604-029
A31: 202604-031 | B31: 一樓收碗區區櫃台門壞掉.修好又壞掉 | C31: 1F | D31: 46132.798 | E31: 已辦驗 | F31: 6.7 天 | G31: - | K31: =VLOOKUP(A31,原始數據!A:A,1,0) -> 202604-031
A32: 202604-030 | B32: 一樓收碗區區櫃台門壞掉 | C32: 1F | D32: 46132.79 | E32: 已辦驗 | F32: 6.7 天 | G32: - | K32: =VLOOKUP(A32,原始數據!A:A,1,0) -> 202604-030
A33: 202604-032 | B33: 1樓牪牛肉側門關不起來 | C33: 1F | D33: 46133.689 | E33: 已辦驗 | F33: 2.6 天 | G33: - | K33: =VLOOKUP(A33,原始數據!A:A,1,0) -> 202604-032
A34: 202604-033 | B34: 植福路樂群三路口三角招牌電源插座安裝 | D34: 46134.419 | E34: - | F34: 6.0 天 | G34: - | K34: =VLOOKUP(A34,原始數據!A:A,1,0) -> 202604-033
A35: 202604-034 | B35: 植福路3面輸出牆的格柵天花板，需要新增6個電線接口 | C35: 1F | D35: 46134.438 | E35: - | F35: 6.0 天 | G35: - | K35: =VLOOKUP(A35,原始數據!A:A,1,0) -> 202604-034
A36: 202604-036 | B36: 4樓愛心廁所 紅色按鈕加裝壓克力盒 | C36: 4F | D36: 46135.596 | E36: 處理中 | F36: 0.1 天 | G36: - | K36: =VLOOKUP(A36,原始數據!A:A,1,0) -> 202604-036
A37: 202604-035 | B37: 戶外餐車--旨燕拉麵，電子鎖電力不足 | C37: 1F | D37: 46135.597 | E37: 待營業回應. | F37: 0.9 天 | G37: - | K37: =VLOOKUP(A37,原始數據!A:A,1,0) -> 202604-035
A38: 202604-037 | B38: 1f 牪肉舖 水管破洞漏水，已購買新水管，請工務安裝，需收費 | C38: 1F | D38: 46135.697 | E38: 已辦驗 | F38: 5.7 天 | G38: - | H38: 牪肉舖 | K38: =VLOOKUP(A38,原始數據!A:A,1,0) -> 202604-037
A39: 202604-041 | B39: B2水管漏水 | C39: B2F | D39: 46137.64 | E39: 已辦驗 | F39: 3.1 天 | G39: - | K39: =VLOOKUP(A39,原始數據!A:A,1,0) -> 202604-041
A40: 202604-040 | B40: 漢堡世家電子鎖沒電 | C40: 1F | D40: 46137.512 | E40: 已辦驗 | F40: 3.2 天 | G40: - | K40: =VLOOKUP(A40,原始數據!A:A,1,0) -> 202604-040
...
